2020-02-12 00:58:17,154 ERROR: Exception on /index [GET] [in /home/alt/microblog/venv/lib/python3.6/site-packages/flask/app.py:1891]
Traceback (most recent call last):
  File "/home/alt/microblog/venv/lib/python3.6/site-packages/flask/app.py", line 2446, in wsgi_app
    response = self.full_dispatch_request()
  File "/home/alt/microblog/venv/lib/python3.6/site-packages/flask/app.py", line 1951, in full_dispatch_request
    rv = self.handle_user_exception(e)
  File "/home/alt/microblog/venv/lib/python3.6/site-packages/flask/app.py", line 1820, in handle_user_exception
    reraise(exc_type, exc_value, tb)
  File "/home/alt/microblog/venv/lib/python3.6/site-packages/flask/_compat.py", line 39, in reraise
    raise value
  File "/home/alt/microblog/venv/lib/python3.6/site-packages/flask/app.py", line 1949, in full_dispatch_request
    rv = self.dispatch_request()
  File "/home/alt/microblog/venv/lib/python3.6/site-packages/flask/app.py", line 1935, in dispatch_request
    return self.view_functions[rule.endpoint](**req.view_args)
  File "./app/routes.py", line 24, in index
    posts = current_user.followed_posts().paginate(
  File "/home/alt/microblog/venv/lib/python3.6/site-packages/werkzeug/local.py", line 347, in __getattr__
    return getattr(self._get_current_object(), name)
AttributeError: 'AnonymousUserMixin' object has no attribute 'followed_posts'
2020-02-12 01:18:17,498 INFO: Microblog startup [in ./microblog.py:38]
2020-02-12 01:19:57,105 INFO: Microblog startup [in ./microblog.py:38]
2020-02-12 01:22:18,427 INFO: Microblog startup [in ./microblog.py:38]
2020-02-12 01:22:26,002 ERROR: Exception on /user/1 [GET] [in /home/alt/microblog/venv/lib/python3.6/site-packages/flask/app.py:1891]
Traceback (most recent call last):
  File "/home/alt/microblog/venv/lib/python3.6/site-packages/flask/app.py", line 2446, in wsgi_app
    response = self.full_dispatch_request()
  File "/home/alt/microblog/venv/lib/python3.6/site-packages/flask/app.py", line 1951, in full_dispatch_request
    rv = self.handle_user_exception(e)
  File "/home/alt/microblog/venv/lib/python3.6/site-packages/flask/app.py", line 1820, in handle_user_exception
    reraise(exc_type, exc_value, tb)
  File "/home/alt/microblog/venv/lib/python3.6/site-packages/flask/_compat.py", line 39, in reraise
    raise value
  File "/home/alt/microblog/venv/lib/python3.6/site-packages/flask/app.py", line 1949, in full_dispatch_request
    rv = self.dispatch_request()
  File "/home/alt/microblog/venv/lib/python3.6/site-packages/flask/app.py", line 1935, in dispatch_request
    return self.view_functions[rule.endpoint](**req.view_args)
  File "/home/alt/microblog/venv/lib/python3.6/site-packages/flask_login/utils.py", line 261, in decorated_view
    return func(*args, **kwargs)
  File "./app/routes.py", line 92, in user
    return render_template('user.html', user=user, posts=posts)
  File "/home/alt/microblog/venv/lib/python3.6/site-packages/flask/templating.py", line 140, in render_template
    ctx.app,
  File "/home/alt/microblog/venv/lib/python3.6/site-packages/flask/templating.py", line 120, in _render
    rv = template.render(context)
  File "/home/alt/microblog/venv/lib/python3.6/site-packages/jinja2/environment.py", line 1090, in render
    self.environment.handle_exception()
  File "/home/alt/microblog/venv/lib/python3.6/site-packages/jinja2/environment.py", line 832, in handle_exception
    reraise(*rewrite_traceback_stack(source=source))
  File "/home/alt/microblog/venv/lib/python3.6/site-packages/jinja2/_compat.py", line 28, in reraise
    raise value.with_traceback(tb)
  File "/home/alt/microblog/app/templates/user.html", line 1, in top-level template code
    {% extends "base.html" %}
  File "/home/alt/microblog/app/templates/base.html", line 69, in top-level template code
    {% block content %}{% endblock %}
  File "/home/alt/microblog/app/templates/user.html", line 6, in block "content"
    <td><img src="{{ user.avatar() }}">
TypeError: avatar() missing 1 required positional argument: 'size'
2020-02-12 01:22:33,303 ERROR: Exception on /user/1 [GET] [in /home/alt/microblog/venv/lib/python3.6/site-packages/flask/app.py:1891]
Traceback (most recent call last):
  File "/home/alt/microblog/venv/lib/python3.6/site-packages/flask/app.py", line 2446, in wsgi_app
    response = self.full_dispatch_request()
  File "/home/alt/microblog/venv/lib/python3.6/site-packages/flask/app.py", line 1951, in full_dispatch_request
    rv = self.handle_user_exception(e)
  File "/home/alt/microblog/venv/lib/python3.6/site-packages/flask/app.py", line 1820, in handle_user_exception
    reraise(exc_type, exc_value, tb)
  File "/home/alt/microblog/venv/lib/python3.6/site-packages/flask/_compat.py", line 39, in reraise
    raise value
  File "/home/alt/microblog/venv/lib/python3.6/site-packages/flask/app.py", line 1949, in full_dispatch_request
    rv = self.dispatch_request()
  File "/home/alt/microblog/venv/lib/python3.6/site-packages/flask/app.py", line 1935, in dispatch_request
    return self.view_functions[rule.endpoint](**req.view_args)
  File "/home/alt/microblog/venv/lib/python3.6/site-packages/flask_login/utils.py", line 261, in decorated_view
    return func(*args, **kwargs)
  File "./app/routes.py", line 92, in user
    return render_template('user.html', user=user, posts=posts)
  File "/home/alt/microblog/venv/lib/python3.6/site-packages/flask/templating.py", line 140, in render_template
    ctx.app,
  File "/home/alt/microblog/venv/lib/python3.6/site-packages/flask/templating.py", line 120, in _render
    rv = template.render(context)
  File "/home/alt/microblog/venv/lib/python3.6/site-packages/jinja2/environment.py", line 1090, in render
    self.environment.handle_exception()
  File "/home/alt/microblog/venv/lib/python3.6/site-packages/jinja2/environment.py", line 832, in handle_exception
    reraise(*rewrite_traceback_stack(source=source))
  File "/home/alt/microblog/venv/lib/python3.6/site-packages/jinja2/_compat.py", line 28, in reraise
    raise value.with_traceback(tb)
  File "/home/alt/microblog/app/templates/user.html", line 1, in top-level template code
    {% extends "base.html" %}
  File "/home/alt/microblog/app/templates/base.html", line 69, in top-level template code
    {% block content %}{% endblock %}
  File "/home/alt/microblog/app/templates/user.html", line 6, in block "content"
    <td><img src="{{ user.avatar() }}">
TypeError: avatar() missing 1 required positional argument: 'size'
2020-02-12 01:22:52,649 INFO: Microblog startup [in ./microblog.py:38]
2020-02-12 01:25:21,750 INFO: Microblog startup [in ./microblog.py:38]
2020-02-12 17:24:37,172 INFO: Microblog startup [in ./microblog.py:38]
2020-02-13 16:59:45,421 INFO: Microblog startup [in ./microblog.py:38]
2020-02-20 14:43:08,342 INFO: Microblog startup [in ./microblog.py:38]
2020-02-20 15:00:37,958 INFO: Microblog startup [in ./microblog.py:38]
2020-02-21 12:04:53,138 INFO: Microblog startup [in ./microblog.py:38]
2020-02-21 18:40:03,099 INFO: Microblog startup [in ./microblog.py:38]
2020-02-21 18:41:58,059 INFO: Microblog startup [in ./microblog.py:38]
2020-02-21 19:57:03,216 INFO: Microblog startup [in ./microblog.py:38]
2020-02-21 20:05:33,611 INFO: Microblog startup [in ./microblog.py:38]
2020-02-21 20:07:08,530 INFO: Microblog startup [in ./microblog.py:38]
2020-02-21 20:07:18,410 ERROR: Exception on /game [GET] [in /home/alt/microblog/venv/lib/python3.6/site-packages/flask/app.py:1891]
Traceback (most recent call last):
  File "/home/alt/microblog/venv/lib/python3.6/site-packages/flask/app.py", line 2446, in wsgi_app
    response = self.full_dispatch_request()
  File "/home/alt/microblog/venv/lib/python3.6/site-packages/flask/app.py", line 1951, in full_dispatch_request
    rv = self.handle_user_exception(e)
  File "/home/alt/microblog/venv/lib/python3.6/site-packages/flask/app.py", line 1820, in handle_user_exception
    reraise(exc_type, exc_value, tb)
  File "/home/alt/microblog/venv/lib/python3.6/site-packages/flask/_compat.py", line 39, in reraise
    raise value
  File "/home/alt/microblog/venv/lib/python3.6/site-packages/flask/app.py", line 1949, in full_dispatch_request
    rv = self.dispatch_request()
  File "/home/alt/microblog/venv/lib/python3.6/site-packages/flask/app.py", line 1935, in dispatch_request
    return self.view_functions[rule.endpoint](**req.view_args)
  File "/home/alt/microblog/venv/lib/python3.6/site-packages/flask_login/utils.py", line 261, in decorated_view
    return func(*args, **kwargs)
  File "./app/routes.py", line 166, in game
    return game_ftbl()
NameError: name 'game_ftbl' is not defined
2020-02-21 20:36:10,931 ERROR: Exception on /game [GET] [in /home/alt/microblog/venv/lib/python3.6/site-packages/flask/app.py:1891]
Traceback (most recent call last):
  File "/home/alt/microblog/venv/lib/python3.6/site-packages/flask/app.py", line 2446, in wsgi_app
    response = self.full_dispatch_request()
  File "/home/alt/microblog/venv/lib/python3.6/site-packages/flask/app.py", line 1951, in full_dispatch_request
    rv = self.handle_user_exception(e)
  File "/home/alt/microblog/venv/lib/python3.6/site-packages/flask/app.py", line 1820, in handle_user_exception
    reraise(exc_type, exc_value, tb)
  File "/home/alt/microblog/venv/lib/python3.6/site-packages/flask/_compat.py", line 39, in reraise
    raise value
  File "/home/alt/microblog/venv/lib/python3.6/site-packages/flask/app.py", line 1949, in full_dispatch_request
    rv = self.dispatch_request()
  File "/home/alt/microblog/venv/lib/python3.6/site-packages/flask/app.py", line 1935, in dispatch_request
    return self.view_functions[rule.endpoint](**req.view_args)
  File "/home/alt/microblog/venv/lib/python3.6/site-packages/flask_login/utils.py", line 261, in decorated_view
    return func(*args, **kwargs)
  File "./app/routes.py", line 166, in game
    return game_ftbl()
NameError: name 'game_ftbl' is not defined
2020-02-21 20:46:11,074 INFO: Microblog startup [in ./microblog.py:38]
2020-02-21 20:56:45,727 INFO: Microblog startup [in ./microblog.py:38]
2020-02-21 20:58:09,971 INFO: Microblog startup [in /home/alt/microblog/microblog.py:38]
2020-02-21 21:12:24,947 INFO: Microblog startup [in /home/alt/microblog/microblog.py:38]
