2020-02-11 12:21:48,763 ERROR: Exception on /index [GET] [in /home/alt/microblog/venv/lib/python3.6/site-packages/flask/app.py:1891]
Traceback (most recent call last):
  File "/home/alt/microblog/venv/lib/python3.6/site-packages/flask/app.py", line 2446, in wsgi_app
    response = self.full_dispatch_request()
  File "/home/alt/microblog/venv/lib/python3.6/site-packages/flask/app.py", line 1951, in full_dispatch_request
    rv = self.handle_user_exception(e)
  File "/home/alt/microblog/venv/lib/python3.6/site-packages/flask/app.py", line 1820, in handle_user_exception
    reraise(exc_type, exc_value, tb)
  File "/home/alt/microblog/venv/lib/python3.6/site-packages/flask/_compat.py", line 39, in reraise
    raise value
  File "/home/alt/microblog/venv/lib/python3.6/site-packages/flask/app.py", line 1949, in full_dispatch_request
    rv = self.dispatch_request()
  File "/home/alt/microblog/venv/lib/python3.6/site-packages/flask/app.py", line 1935, in dispatch_request
    return self.view_functions[rule.endpoint](**req.view_args)
  File "/home/alt/microblog/app/routes.py", line 15, in index
    return render_template('index.html', title='Home')
  File "/home/alt/microblog/venv/lib/python3.6/site-packages/flask/templating.py", line 140, in render_template
    ctx.app,
  File "/home/alt/microblog/venv/lib/python3.6/site-packages/flask/templating.py", line 120, in _render
    rv = template.render(context)
  File "/home/alt/microblog/venv/lib/python3.6/site-packages/jinja2/environment.py", line 1090, in render
    self.environment.handle_exception()
  File "/home/alt/microblog/venv/lib/python3.6/site-packages/jinja2/environment.py", line 832, in handle_exception
    reraise(*rewrite_traceback_stack(source=source))
  File "/home/alt/microblog/venv/lib/python3.6/site-packages/jinja2/_compat.py", line 28, in reraise
    raise value.with_traceback(tb)
  File "/home/alt/microblog/app/templates/index.html", line 1, in top-level template code
    {% extends "base.html" %}
  File "/home/alt/microblog/app/templates/base.html", line 71, in top-level template code
    {% block content %}{% endblock %}
  File "/home/alt/microblog/app/templates/index.html", line 9, in block "content"
    {{ form.hidden_tag() }}
  File "/home/alt/microblog/venv/lib/python3.6/site-packages/jinja2/environment.py", line 471, in getattr
    return getattr(obj, attribute)
jinja2.exceptions.UndefinedError: 'form' is undefined
2020-02-11 12:24:36,241 INFO: Microblog startup [in /home/alt/microblog/microblog.py:38]
2020-02-11 12:24:57,412 INFO: Microblog startup [in /home/alt/microblog/microblog.py:38]
2020-02-11 12:26:53,518 INFO: Microblog startup [in ./microblog.py:38]
2020-02-11 13:47:07,447 INFO: Microblog startup [in ./microblog.py:38]
2020-02-11 13:47:40,426 INFO: Microblog startup [in ./microblog.py:38]
2020-02-11 13:50:17,756 INFO: Microblog startup [in ./microblog.py:38]
2020-02-11 13:51:17,070 INFO: Microblog startup [in ./microblog.py:38]
2020-02-11 15:58:58,495 INFO: Microblog startup [in /home/alt/microblog/microblog.py:38]
2020-02-11 15:59:10,504 INFO: Microblog startup [in /home/alt/microblog/microblog.py:38]
2020-02-11 16:46:39,851 INFO: Microblog startup [in /home/alt/microblog/microblog.py:38]
2020-02-11 17:35:47,130 ERROR: Exception on /user/Alex [GET] [in /home/alt/microblog/venv/lib/python3.6/site-packages/flask/app.py:1891]
Traceback (most recent call last):
  File "/home/alt/microblog/venv/lib/python3.6/site-packages/flask/app.py", line 2446, in wsgi_app
    response = self.full_dispatch_request()
  File "/home/alt/microblog/venv/lib/python3.6/site-packages/flask/app.py", line 1951, in full_dispatch_request
    rv = self.handle_user_exception(e)
  File "/home/alt/microblog/venv/lib/python3.6/site-packages/flask/app.py", line 1820, in handle_user_exception
    reraise(exc_type, exc_value, tb)
  File "/home/alt/microblog/venv/lib/python3.6/site-packages/flask/_compat.py", line 39, in reraise
    raise value
  File "/home/alt/microblog/venv/lib/python3.6/site-packages/flask/app.py", line 1949, in full_dispatch_request
    rv = self.dispatch_request()
  File "/home/alt/microblog/venv/lib/python3.6/site-packages/flask/app.py", line 1935, in dispatch_request
    return self.view_functions[rule.endpoint](**req.view_args)
  File "/home/alt/microblog/venv/lib/python3.6/site-packages/flask_login/utils.py", line 261, in decorated_view
    return func(*args, **kwargs)
  File "./app/routes.py", line 84, in user
    return render_template('user.html', user=user, posts=posts)
  File "/home/alt/microblog/venv/lib/python3.6/site-packages/flask/templating.py", line 140, in render_template
    ctx.app,
  File "/home/alt/microblog/venv/lib/python3.6/site-packages/flask/templating.py", line 120, in _render
    rv = template.render(context)
  File "/home/alt/microblog/venv/lib/python3.6/site-packages/jinja2/environment.py", line 1090, in render
    self.environment.handle_exception()
  File "/home/alt/microblog/venv/lib/python3.6/site-packages/jinja2/environment.py", line 832, in handle_exception
    reraise(*rewrite_traceback_stack(source=source))
  File "/home/alt/microblog/venv/lib/python3.6/site-packages/jinja2/_compat.py", line 28, in reraise
    raise value.with_traceback(tb)
  File "/home/alt/microblog/app/templates/user.html", line 1, in top-level template code
    {% extends "base.html" %}
  File "/home/alt/microblog/app/templates/base.html", line 71, in top-level template code
    {% block content %}{% endblock %}
  File "/home/alt/microblog/app/templates/user.html", line 10, in block "content"
    <p>{{ user.followers.count() }} followers, {{ user.followed.count() }} following.</p>
  File "/home/alt/microblog/venv/lib/python3.6/site-packages/jinja2/environment.py", line 471, in getattr
    return getattr(obj, attribute)
jinja2.exceptions.UndefinedError: 'app.models.User object' has no attribute 'followers'
2020-02-11 17:36:13,036 ERROR: Exception on /user/1 [GET] [in /home/alt/microblog/venv/lib/python3.6/site-packages/flask/app.py:1891]
Traceback (most recent call last):
  File "/home/alt/microblog/venv/lib/python3.6/site-packages/flask/app.py", line 2446, in wsgi_app
    response = self.full_dispatch_request()
  File "/home/alt/microblog/venv/lib/python3.6/site-packages/flask/app.py", line 1951, in full_dispatch_request
    rv = self.handle_user_exception(e)
  File "/home/alt/microblog/venv/lib/python3.6/site-packages/flask/app.py", line 1820, in handle_user_exception
    reraise(exc_type, exc_value, tb)
  File "/home/alt/microblog/venv/lib/python3.6/site-packages/flask/_compat.py", line 39, in reraise
    raise value
  File "/home/alt/microblog/venv/lib/python3.6/site-packages/flask/app.py", line 1949, in full_dispatch_request
    rv = self.dispatch_request()
  File "/home/alt/microblog/venv/lib/python3.6/site-packages/flask/app.py", line 1935, in dispatch_request
    return self.view_functions[rule.endpoint](**req.view_args)
  File "/home/alt/microblog/venv/lib/python3.6/site-packages/flask_login/utils.py", line 261, in decorated_view
    return func(*args, **kwargs)
  File "./app/routes.py", line 84, in user
    return render_template('user.html', user=user, posts=posts)
  File "/home/alt/microblog/venv/lib/python3.6/site-packages/flask/templating.py", line 140, in render_template
    ctx.app,
  File "/home/alt/microblog/venv/lib/python3.6/site-packages/flask/templating.py", line 120, in _render
    rv = template.render(context)
  File "/home/alt/microblog/venv/lib/python3.6/site-packages/jinja2/environment.py", line 1090, in render
    self.environment.handle_exception()
  File "/home/alt/microblog/venv/lib/python3.6/site-packages/jinja2/environment.py", line 832, in handle_exception
    reraise(*rewrite_traceback_stack(source=source))
  File "/home/alt/microblog/venv/lib/python3.6/site-packages/jinja2/_compat.py", line 28, in reraise
    raise value.with_traceback(tb)
  File "/home/alt/microblog/app/templates/user.html", line 1, in top-level template code
    {% extends "base.html" %}
  File "/home/alt/microblog/app/templates/base.html", line 71, in top-level template code
    {% block content %}{% endblock %}
  File "/home/alt/microblog/app/templates/user.html", line 10, in block "content"
    <p>{{ user.followers.count() }} followers, {{ user.followed.count() }} following.</p>
  File "/home/alt/microblog/venv/lib/python3.6/site-packages/jinja2/environment.py", line 471, in getattr
    return getattr(obj, attribute)
jinja2.exceptions.UndefinedError: 'app.models.User object' has no attribute 'followers'
2020-02-11 17:36:21,806 INFO: Microblog startup [in /home/alt/microblog/microblog.py:38]
2020-02-11 17:39:03,088 INFO: Microblog startup [in /home/alt/microblog/microblog.py:38]
2020-02-11 17:40:32,134 INFO: Microblog startup [in /home/alt/microblog/microblog.py:38]
2020-02-11 17:43:03,553 INFO: Microblog startup [in /home/alt/microblog/microblog.py:38]
2020-02-11 18:08:57,727 INFO: Microblog startup [in ./microblog.py:38]
2020-02-11 18:11:34,927 INFO: Microblog startup [in ./microblog.py:38]
