2020-02-11 18:11:37,303 ERROR: Exception on /index [GET] [in /home/alt/microblog/venv/lib/python3.6/site-packages/flask/app.py:1891]
Traceback (most recent call last):
  File "/home/alt/microblog/venv/lib/python3.6/site-packages/flask/app.py", line 2446, in wsgi_app
    response = self.full_dispatch_request()
  File "/home/alt/microblog/venv/lib/python3.6/site-packages/flask/app.py", line 1951, in full_dispatch_request
    rv = self.handle_user_exception(e)
  File "/home/alt/microblog/venv/lib/python3.6/site-packages/flask/app.py", line 1820, in handle_user_exception
    reraise(exc_type, exc_value, tb)
  File "/home/alt/microblog/venv/lib/python3.6/site-packages/flask/_compat.py", line 39, in reraise
    raise value
  File "/home/alt/microblog/venv/lib/python3.6/site-packages/flask/app.py", line 1949, in full_dispatch_request
    rv = self.dispatch_request()
  File "/home/alt/microblog/venv/lib/python3.6/site-packages/flask/app.py", line 1935, in dispatch_request
    return self.view_functions[rule.endpoint](**req.view_args)
  File "./app/routes.py", line 22, in index
    posts = current_user.followed_posts().all()
  File "/home/alt/microblog/venv/lib/python3.6/site-packages/werkzeug/local.py", line 347, in __getattr__
    return getattr(self._get_current_object(), name)
AttributeError: 'AnonymousUserMixin' object has no attribute 'followed_posts'
2020-02-11 18:11:56,022 INFO: Microblog startup [in /home/alt/microblog/microblog.py:38]
2020-02-11 18:12:11,030 ERROR: Exception on /index [GET] [in /home/alt/microblog/venv/lib/python3.6/site-packages/flask/app.py:1891]
Traceback (most recent call last):
  File "/home/alt/microblog/venv/lib/python3.6/site-packages/flask/app.py", line 2446, in wsgi_app
    response = self.full_dispatch_request()
  File "/home/alt/microblog/venv/lib/python3.6/site-packages/flask/app.py", line 1951, in full_dispatch_request
    rv = self.handle_user_exception(e)
  File "/home/alt/microblog/venv/lib/python3.6/site-packages/flask/app.py", line 1820, in handle_user_exception
    reraise(exc_type, exc_value, tb)
  File "/home/alt/microblog/venv/lib/python3.6/site-packages/flask/_compat.py", line 39, in reraise
    raise value
  File "/home/alt/microblog/venv/lib/python3.6/site-packages/flask/app.py", line 1949, in full_dispatch_request
    rv = self.dispatch_request()
  File "/home/alt/microblog/venv/lib/python3.6/site-packages/flask/app.py", line 1935, in dispatch_request
    return self.view_functions[rule.endpoint](**req.view_args)
  File "/home/alt/microblog/app/routes.py", line 22, in index
    posts = current_user.followed_posts().all()
  File "/home/alt/microblog/venv/lib/python3.6/site-packages/werkzeug/local.py", line 347, in __getattr__
    return getattr(self._get_current_object(), name)
AttributeError: 'AnonymousUserMixin' object has no attribute 'followed_posts'
2020-02-11 18:14:04,602 INFO: Microblog startup [in /home/alt/microblog/microblog.py:38]
2020-02-11 18:14:06,921 ERROR: Exception on /index [GET] [in /home/alt/microblog/venv/lib/python3.6/site-packages/flask/app.py:1891]
Traceback (most recent call last):
  File "/home/alt/microblog/venv/lib/python3.6/site-packages/flask/app.py", line 2446, in wsgi_app
    response = self.full_dispatch_request()
  File "/home/alt/microblog/venv/lib/python3.6/site-packages/flask/app.py", line 1952, in full_dispatch_request
    return self.finalize_request(rv)
  File "/home/alt/microblog/venv/lib/python3.6/site-packages/flask/app.py", line 1967, in finalize_request
    response = self.make_response(rv)
  File "/home/alt/microblog/venv/lib/python3.6/site-packages/flask/app.py", line 2097, in make_response
    "The view function did not return a valid response. The"
TypeError: The view function did not return a valid response. The function either returned None or ended without a return statement.
2020-02-11 18:14:13,576 ERROR: Exception on /index [GET] [in /home/alt/microblog/venv/lib/python3.6/site-packages/flask/app.py:1891]
Traceback (most recent call last):
  File "/home/alt/microblog/venv/lib/python3.6/site-packages/flask/app.py", line 2446, in wsgi_app
    response = self.full_dispatch_request()
  File "/home/alt/microblog/venv/lib/python3.6/site-packages/flask/app.py", line 1952, in full_dispatch_request
    return self.finalize_request(rv)
  File "/home/alt/microblog/venv/lib/python3.6/site-packages/flask/app.py", line 1967, in finalize_request
    response = self.make_response(rv)
  File "/home/alt/microblog/venv/lib/python3.6/site-packages/flask/app.py", line 2097, in make_response
    "The view function did not return a valid response. The"
TypeError: The view function did not return a valid response. The function either returned None or ended without a return statement.
2020-02-11 19:59:19,385 ERROR: Exception on /index [GET] [in /home/alt/microblog/venv/lib/python3.6/site-packages/flask/app.py:1891]
Traceback (most recent call last):
  File "/home/alt/microblog/venv/lib/python3.6/site-packages/flask/app.py", line 2446, in wsgi_app
    response = self.full_dispatch_request()
  File "/home/alt/microblog/venv/lib/python3.6/site-packages/flask/app.py", line 1952, in full_dispatch_request
    return self.finalize_request(rv)
  File "/home/alt/microblog/venv/lib/python3.6/site-packages/flask/app.py", line 1967, in finalize_request
    response = self.make_response(rv)
  File "/home/alt/microblog/venv/lib/python3.6/site-packages/flask/app.py", line 2097, in make_response
    "The view function did not return a valid response. The"
TypeError: The view function did not return a valid response. The function either returned None or ended without a return statement.
2020-02-11 20:00:19,704 ERROR: Exception on /index [GET] [in /home/alt/microblog/venv/lib/python3.6/site-packages/flask/app.py:1891]
Traceback (most recent call last):
  File "/home/alt/microblog/venv/lib/python3.6/site-packages/flask/app.py", line 2446, in wsgi_app
    response = self.full_dispatch_request()
  File "/home/alt/microblog/venv/lib/python3.6/site-packages/flask/app.py", line 1952, in full_dispatch_request
    return self.finalize_request(rv)
  File "/home/alt/microblog/venv/lib/python3.6/site-packages/flask/app.py", line 1967, in finalize_request
    response = self.make_response(rv)
  File "/home/alt/microblog/venv/lib/python3.6/site-packages/flask/app.py", line 2097, in make_response
    "The view function did not return a valid response. The"
TypeError: The view function did not return a valid response. The function either returned None or ended without a return statement.
2020-02-11 20:00:22,765 ERROR: Exception on /index [GET] [in /home/alt/microblog/venv/lib/python3.6/site-packages/flask/app.py:1891]
Traceback (most recent call last):
  File "/home/alt/microblog/venv/lib/python3.6/site-packages/flask/app.py", line 2446, in wsgi_app
    response = self.full_dispatch_request()
  File "/home/alt/microblog/venv/lib/python3.6/site-packages/flask/app.py", line 1952, in full_dispatch_request
    return self.finalize_request(rv)
  File "/home/alt/microblog/venv/lib/python3.6/site-packages/flask/app.py", line 1967, in finalize_request
    response = self.make_response(rv)
  File "/home/alt/microblog/venv/lib/python3.6/site-packages/flask/app.py", line 2097, in make_response
    "The view function did not return a valid response. The"
TypeError: The view function did not return a valid response. The function either returned None or ended without a return statement.
2020-02-11 20:00:27,343 ERROR: Exception on /index [GET] [in /home/alt/microblog/venv/lib/python3.6/site-packages/flask/app.py:1891]
Traceback (most recent call last):
  File "/home/alt/microblog/venv/lib/python3.6/site-packages/flask/app.py", line 2446, in wsgi_app
    response = self.full_dispatch_request()
  File "/home/alt/microblog/venv/lib/python3.6/site-packages/flask/app.py", line 1952, in full_dispatch_request
    return self.finalize_request(rv)
  File "/home/alt/microblog/venv/lib/python3.6/site-packages/flask/app.py", line 1967, in finalize_request
    response = self.make_response(rv)
  File "/home/alt/microblog/venv/lib/python3.6/site-packages/flask/app.py", line 2097, in make_response
    "The view function did not return a valid response. The"
TypeError: The view function did not return a valid response. The function either returned None or ended without a return statement.
2020-02-11 20:37:05,469 ERROR: Exception on /index [GET] [in /home/alt/microblog/venv/lib/python3.6/site-packages/flask/app.py:1891]
Traceback (most recent call last):
  File "/home/alt/microblog/venv/lib/python3.6/site-packages/flask/app.py", line 2446, in wsgi_app
    response = self.full_dispatch_request()
  File "/home/alt/microblog/venv/lib/python3.6/site-packages/flask/app.py", line 1952, in full_dispatch_request
    return self.finalize_request(rv)
  File "/home/alt/microblog/venv/lib/python3.6/site-packages/flask/app.py", line 1967, in finalize_request
    response = self.make_response(rv)
  File "/home/alt/microblog/venv/lib/python3.6/site-packages/flask/app.py", line 2097, in make_response
    "The view function did not return a valid response. The"
TypeError: The view function did not return a valid response. The function either returned None or ended without a return statement.
2020-02-11 21:26:19,058 INFO: Microblog startup [in ./microblog.py:38]
2020-02-11 22:52:40,635 INFO: Microblog startup [in ./microblog.py:38]
2020-02-11 22:54:09,753 INFO: Microblog startup [in ./microblog.py:38]
2020-02-11 23:02:40,336 INFO: Microblog startup [in ./microblog.py:38]
2020-02-11 23:11:37,420 INFO: Microblog startup [in ./microblog.py:38]
2020-02-11 23:16:14,642 INFO: Microblog startup [in ./microblog.py:38]
2020-02-11 23:17:29,644 INFO: Microblog startup [in ./microblog.py:38]
2020-02-11 23:18:06,260 INFO: Microblog startup [in ./microblog.py:38]
2020-02-11 23:20:27,587 INFO: Microblog startup [in ./microblog.py:38]
2020-02-11 23:34:31,956 INFO: Microblog startup [in ./microblog.py:38]
2020-02-12 00:58:12,194 INFO: Microblog startup [in ./microblog.py:38]
